This block appeared over and over

All but the last logs are expected, since that was from the "who dareth" thing.  But the ERROR is a mystery.

```
django-1                    | 2024-11-04 15:33:19,120 WARNING  /bridge/.venv/lib/python3.12/site-packages/sentry_sdk/integrations/django/middleware.py: 174
django-1                    | 2024-11-04 15:33:19,126 WARNING  /bridge/.venv/lib/python3.12/site-packages/debug_toolbar/middleware.py: 72
django-1                    | 2024-11-04 15:33:19,126 WARNING  /bridge/.venv/lib/python3.12/site-packages/django/core/handlers/exception.py: 55
django-1                    | 2024-11-04 15:33:19,126 WARNING  /bridge/.venv/lib/python3.12/site-packages/sentry_sdk/integrations/django/middleware.py: 174
django-1                    | 2024-11-04 15:33:19,126 WARNING  /bridge/.venv/lib/python3.12/site-packages/django/utils/deprecation.py: 129
django-1                    | 2024-11-04 15:33:19,126 WARNING  /bridge/.venv/lib/python3.12/site-packages/django/core/handlers/exception.py: 55
django-1                    | 2024-11-04 15:33:19,127 WARNING  /bridge/.venv/lib/python3.12/site-packages/sentry_sdk/integrations/django/middleware.py: 174
django-1                    | 2024-11-04 15:33:19,127 WARNING  /bridge/.venv/lib/python3.12/site-packages/whitenoise/middleware.py: 123
django-1                    | 2024-11-04 15:33:19,127 WARNING  /bridge/.venv/lib/python3.12/site-packages/asgiref/sync.py: 244
django-1                    | 2024-11-04 15:33:19,127 WARNING  /bridge/.venv/lib/python3.12/site-packages/asgiref/current_thread_executor.py: 81
django-1                    | 2024-11-04 15:33:19,127 WARNING  /bridge/.venv/lib/python3.12/site-packages/asgiref/current_thread_executor.py: 40
django-1                    | 2024-11-04 15:33:19,127 WARNING  /bridge/.venv/lib/python3.12/site-packages/asgiref/sync.py: 522
django-1                    | 2024-11-04 15:33:19,127 WARNING  /bridge/.venv/lib/python3.12/site-packages/django/utils/decorators.py: 186
django-1                    | 2024-11-04 15:33:19,127 WARNING  /bridge/.venv/lib/python3.12/site-packages/django/contrib/auth/decorators.py: 60
django-1                    | 2024-11-04 15:33:19,127 WARNING  /bridge/project/app/views/misc.py: 38
django-1                    | 2024-11-04 15:33:19,127 WARNING  /bridge/project/app/views/hand.py: 499
django-1                    | 2024-11-04 15:33:19,127 WARNING  /bridge/project/app/views/hand.py: 257
django-1                    | 2024-11-04 15:33:19,127 WARNING  /bridge/project/app/views/hand.py: 94
django-1                    | 2024-11-04 15:33:19,127 WARNING  /bridge/project/app/models/hand.py: 347
django-1                    | 2024-11-04 15:33:19,127 WARNING  /bridge/project/app/models/hand.py: 319
django-1                    | 2024-11-04 15:33:19,127 WARNING  /bridge/project/app/models/hand.py: 226
django-1                    | 2024-11-04 15:33:19,127 WARNING  Who dareth invoke me
django-1                    | 2024-11-04 15:33:19,127 ERROR
```
